Workbook

Sheet Heizkörperfaktoren
A1: Objekt: | E1: Uhlandstr. 12
A2: Objektnummer: | E2: Becker WEG Uhland
A3: HKV-Typ: | E3: Q caloric 5 P3 AL32 oberes Loc
A4: HKV-Nr: | E4: 63
A5: Normtemperatur: | F5: 45292 | G5: bis 31.12.24
A7: Name | B7: Faktor 90 | C7: Straße | D7: Ort | E7: Lage | F7: Nutzer | G7: Geräte-Nr. | H7: Raum | I7: CMID | J7: HK-Art | K7: Länge / ... | L7: Höhe | M7: Tiefe | N7: Teilung | O7: KQ 90/70 | P7: KC 1 | Q7: KC 2 | R7: HKV Nr. | S7: Faktor 90 | T7: HKV-Typ
A9: Becker | B9: 1.717 | C9: Uhlandstr. 12 | D9: Frickenhausen | E9: EG li | G9: 90878776 | H9: BAD | I9: 100000114 | J9: PKKPC | K9: 900 | L9: 550 | M9: 100 | N9: 25 | O9: 2042 | P9: 1.13 | Q9: 2.15 | R9: 63 | S9: 1.717 | T9: Q caloric 5 P3 AL32 oberes Loc
A10: Becker | B10: 0.882 | C10: Uhlandstr. 12 | D10: Frickenhausen | E10: EG li | G10: 90878777 | H10: KÜ | I10: 100000114 | J10: PKPC | K10: 600 | L10: 550 | M10: 70 | N10: 25 | O10: 1049 | P10: 1.13 | Q10: 2.15 | R10: 63 | S10: 0.882 | T10: Q caloric 5 P3 AL32 oberes Loc
A11: Becker | B11: 0.867 | C11: Uhlandstr. 12 | D11: Frickenhausen | E11: EG li | G11: 90878778 | H11: KI1 | I11: 100000114 | J11: PPC | K11: 800 | L11: 550 | M11: 70 | N11: 25 | O11: 1031 | P11: 1.13 | Q11: 2.15 | R11: 63 | S11: 0.867 | T11: Q caloric 5 P3 AL32 oberes Loc
A12: Becker | B12: 0.867 | C12: Uhlandstr. 12 | D12: Frickenhausen | E12: EG li | G12: 90878779 | H12: KI2 | I12: 100000114 | J12: PPC | K12: 800 | L12: 550 | M12: 70 | N12: 25 | O12: 1031 | P12: 1.13 | Q12: 2.15 | R12: 63 | S12: 0.867 | T12: Q caloric 5 P3 AL32 oberes Loc
A13: Becker | B13: 2.289 | C13: Uhlandstr. 12 | D13: Frickenhausen | E13: EG li | G13: 90878780 | H13: WZ1 | I13: 100000114 | J13: PKKPC | K13: 1200 | L13: 550 | M13: 100 | N13: 25 | O13: 2723 | P13: 1.13 | Q13: 2.15 | R13: 63 | S13: 2.289 | T13: Q caloric 5 P3 AL32 oberes Loc
A14: Becker | B14: 1.717 | C14: Uhlandstr. 12 | D14: Frickenhausen | E14: EG li | G14: 90878786 | H14: WZ2 | I14: 100000114 | J14: PKKPC | K14: 900 | L14: 550 | M14: 100 | N14: 25 | O14: 2042 | P14: 1.13 | Q14: 2.15 | R14: 63 | S14: 1.717 | T14: Q caloric 5 P3 AL32 oberes Loc
A15: Becker | B15: 1.175 | C15: Uhlandstr. 12 | D15: Frickenhausen | E15: EG li | G15: 90878787 | H15: KI2 | I15: 100000114 | J15: PKPC | K15: 800 | L15: 550 | M15: 70 | N15: 25 | O15: 1398 | P15: 1.13 | Q15: 2.15 | R15: 63 | S15: 1.175 | T15: Q caloric 5 P3 AL32 oberes Loc
A16: Becker | B16: 1.782 | C16: Uhlandstr. 12 | D16: Frickenhausen | E16: EG li | G16: 90878788 | H16: SZ | I16: 100000119 | J16: PKKPKPC | K16: 700 | L16: 550 | M16: 140 | N16: 25 | O16: 2120 | P16: 1.13 | Q16: 2.15 | R16: 63 | S16: 1.782 | T16: Q caloric 5 P3 AL32 oberes Loc
A17: Drost | B17: 0.588 | C17: Uhlandstr. 12 | D17: Frickenhausen | E17: EG re | G17: 90878790 | H17: FL | I17: 100000114 | J17: PKPC | K17: 400 | L17: 550 | M17: 70 | N17: 25 | O17: 699 | P17: 1.13 | Q17: 2.15 | R17: 63 | S17: 0.588 | T17: Q caloric 5 P3 AL32 oberes Loc
A18: Drost | B18: 1.764 | C18: Uhlandstr. 12 | D18: Frickenhausen | E18: EG re | G18: 90878791 | H18: WZ1 | I18: 100000114 | J18: PKPC | K18: 1200 | L18: 550 | M18: 70 | N18: 25 | O18: 2098 | P18: 1.13 | Q18: 2.15 | R18: 63 | S18: 1.764 | T18: Q caloric 5 P3 AL32 oberes Loc
A19: Drost | B19: 1.175 | C19: Uhlandstr. 12 | D19: Frickenhausen | E19: EG re | G19: 90878792 | H19: WZ2 | I19: 100000114 | J19: PKPC | K19: 800 | L19: 550 | M19: 70 | N19: 25 | O19: 1398 | P19: 1.13 | Q19: 2.15 | R19: 63 | S19: 1.175 | T19: Q caloric 5 P3 AL32 oberes Loc
A20: Drost | B20: 1.175 | C20: Uhlandstr. 12 | D20: Frickenhausen | E20: EG re | G20: 90878793 | H20: WZ3 | I20: 100000114 | J20: PKPC | K20: 800 | L20: 550 | M20: 70 | N20: 25 | O20: 1398 | P20: 1.13 | Q20: 2.15 | R20: 63 | S20: 1.175 | T20: Q caloric 5 P3 AL32 oberes Loc
... A58: Gneiting | B58: 1.144 | C58: Uhlandstr. 12 | D58: Frickenhausen | E58: 2.OG re | G58: 90878831 | H58: BAD | I58: 100000114 | J58: PKKPC | K58: 600 | L58: 550 | M58: 100 | N58: 25 | O58: 1361 | P58: 1.13 | Q58: 2.15 | R58: 63 | S58: 1.144 | T58: Q caloric 5 P3 AL32 oberes Loc

Sheet Hauptabrechnung
A1: Heiz-, Warm- und Kaltwasserkosten Abrechnung 2025
A3: Kostenaufstellung des gesamten Objekts
A5: Heizungsanlage | B5: Wert | C5: Einheiten | D5: Datum Ablesung | F5: 45658 | G5: bis 31.12.25
A7: Brennstoffverbrauch | B7: 39833 | C7: Kwh | D7: 46022 | F7: 3874.89
E8: Summe: | F8: =SUM(F7) -> 3874.89
A9: Faktor für kWh | B9: =SUM(F8/B7) -> 0.097278387 | C9: Euro
A10: Verbrauch Heizung | B10: =SUM(B7-B11) -> 32507.2 | C10: kWh
A11: Verbrauch Wasser | B11: 7325.8 | C11: kWh | D11: 46022
A13: Gesamtwasserbetrag | B13: =SUM(F17+F18) -> 1817.65 | C13: lt. Rechnung
A14: Warmwassermenge | B14: =VALUE(Becker!H31+Drost!H30+Bernsee!H32+Ballestriero!H32+Weber!H31+Gneiting!H37) -> 75.512 | C14: Kubikmeter
A15: Kaltwassermenge | B15: =VALUE(Becker!H36+Drost!H35+Bernsee!H37+Ballestriero!H37+Weber!H36+Gneiting!H43) -> 193.775 | C15: Kubikmeter
A16: Gesamtwassermenge | B16: =SUM(B14+B15) -> 269.287 | C16: Kubikmeter
A17: Kaltwasserkosten | B17: lt. Rechnung | F17: =895.79+826.48 -> 1722.27
A18: Niederschlagswasser | B18: lt. Rechnung | F18: 95.38
A19: ________________________________________________________________
A20: Gesamt | C20: 45659 | F20: =SUM(F8+F17+F18) -> 5692.54
A22: Trennung der Gesamtkosten Heizungsanlage
A23: Heizkosten | B23: Betrag | C23: Anteil | F23: Summe
A25: Brennstoff | B25: =VALUE(B9) -> 0.097278387 | C25: =VALUE(B10) -> 32507.2 | D25: kWh | F25: =SUM(B25*C25) -> 3162.248
A26: ________________________________________________________________
A27: Summe | F27: =SUM(F25) -> 3162.248
A29: Warmwasserkosten | B29: Betrag | C29: Anteil
A30: Brennstoff | B30: =VALUE(B9) -> 0.097278387 | C30: =VALUE(B11) -> 7325.8 | D30: kWh | F30: =SUM(B30*C30) -> 712.64201
A31: Kaltwasser für Warmwasser | B31: =SUM(B13/B16*B14) -> 509.69555 | C31: 1 | F31: =SUM(B31*C31) -> 509.69555
A32: ________________________________________________________________
A33: Summe | F33: =SUM(F30+F31) -> 1222.3376
A34: Gesamtsumme Heizungskosten | F34: =SUM(F27+F33) -> 4384.5856
A36: Kaltwasserkosten | B36: Betrag | C36: Anteil WW
A37: Kaltwasser | B37: =VALUE(F17) -> 1722.27 | C37: =VALUE(B31) -> 509.69555 | F37: =SUM(B37-C37) -> 1212.5744
A38: Niederschlagswasser | B38: =VALUE(F18) -> 95.38 | F38: =VALUE(F18) -> 95.38
A40: ________________________________________________________________
A41: Gesamt | F41: =SUM(F34+F37+F38) -> 5692.54
A42: ________________________________________________________________
A44: Verteilung der Kosten | C44: Euro | D44: Werte
A46: Heizkosten | C46: =SUM(F27) -> 3162.248 | F46: Preis je Einheit | I46: Einheiten | J46: Gesamtbetrag
A47: 30% Grundkosten | C47: =SUM(C46*30%) -> 948.6744 | D47: 414.52 | E47: qm | F47: =SUM(C47/D47) -> 2.2886095 | H47: Prüfsumme: | I47: =SUM(Becker!F4+Drost!F4+Bernsee!F4+Ballestriero!F4+Weber!F4+Gneiting!F4) -> 414.52 | J47: =SUM(Becker!H4+Drost!H4+Bernsee!H4+Ballestriero!H4+Weber!H4+Gneiting!H4) -> 948.6744
A48: 70% Verbrauchskosten | C48: =SUM(C46*70%) -> 2213.5736 | D48: =VALUE(Becker!H27+Drost!H26+Bernsee!H28+Ballestriero!H28+Weber!H27+Gneiting!H32) -> 17664.22 | E48: Punkte | F48: =SUM(C48/D48) -> 0.12531397 | H48: Prüfsumme: | I48: =VALUE(Becker!H27+Drost!H26+Bernsee!H28+Ballestriero!H28+Weber!H27+Gneiting!H32) -> 17664.22 | J48: =SUM(Becker!H5+Drost!H5+Bernsee!H5+Ballestriero!H5+Weber!H5+Gneiting!H5) -> 2213.5736
A50: Warmwasserkosten | C50: =SUM(F33) -> 1222.3376
A51: 30% Grundkosten | C51: =SUM(C50*30%) -> 366.70127 | D51: 414.52 | E51: qm | F51: =SUM(C51/D51) -> 0.88464072 | H51: Prüfsumme: | I51: =SUM(Becker!F8+Drost!F8+Bernsee!F8+Ballestriero!F8+Weber!F8+Gneiting!F8) -> 414.52 | J51: =SUM(Becker!H8+Drost!H8+Bernsee!H8+Ballestriero!H8+Weber!H8+Gneiting!H8) -> 366.70127
A52: 70% Verbrauchskosten | C52: =SUM(C50*70%) -> 855.63629 | D52: =VALUE(B14) -> 75.512 | E52: Kubikmeter | F52: =SUM(C52/D52) -> 11.33113 | H52: Prüfsumme: | I52: =SUM(Becker!H31+Drost!H30+Bernsee!H32+Ballestriero!H32+Weber!H31+Gneiting!H37) -> 75.512 | J52: =SUM(Becker!H9+Drost!H9+Bernsee!H9+Ballestriero!H9+Weber!H9+Gneiting!H9) -> 855.63629
...

Sheet Zahlungen 2025
A1: Ein- und Ausgaben WEG Uhlandstr. 12 , Jahr 2025
B2: Becker | C2: Drost | D2: Bernsee | E2: Ballestriero | F2: Weber | G2: Gneiting | H2: Gesamt | I2: HMT | J2: WEG Rücklagen
A3: 45658 | B3: 290 | C3: 225 | D3: 250 | E3: 210 | F3: 210 | G3: 220 | H3: =SUM(B3+C3+D3+E3+F3+G3) -> 1405 | I3: 200 | J3: 500
A4: 45689 | B4: 290 | C4: 225 | D4: 250 | E4: 210 | F4: 210 | G4: 220 | H4: =SUM(B4+C4+D4+E4+F4+G4) -> 1405 | I4: 200 | J4: 500
A5: 45717 | B5: 290 | C5: 225 | D5: 250 | E5: 210 | F5: 210 | G5: 220 | H5: =SUM(B5+C5+D5+E5+F5+G5) -> 1405 | I5: 200 | J5: 500
A6: 45748 | B6: 290 | C6: 225 | D6: 250 | E6: 210 | F6: 210 | G6: 220 | H6: =SUM(B6+C6+D6+E6+F6+G6) -> 1405 | I6: 200 | J6: 500
A7: 45778 | B7: 290 | C7: 220 | D7: 250 | E7: 210 | F7: 210 | G7: 220 | H7: =SUM(B7+C7+D7+E7+F7+G7) -> 1400 | I7: 200 | J7: 500
A8: 45809 | B8: 290 | C8: 220 | D8: 250 | E8: 210 | F8: 210 | G8: 220 | H8: =SUM(B8+C8+D8+E8+F8+G8) -> 1400 | I8: 200 | J8: 500
A9: 45839 | B9: 290 | C9: 220 | D9: 250 | E9: 210 | F9: 210 | G9: 220 | H9: =SUM(B9+C9+D9+E9+F9+G9) -> 1400 | I9: 200 | J9: 500
A10: 45870 | B10: 290 | C10: 220 | D10: 250 | E10: 210 | F10: 210 | G10: 220 | H10: =SUM(B10+C10+D10+E10+F10+G10) -> 1400 | I10: 200 | J10: 500
A11: 45901 | B11: 290 | C11: 220 | D11: 250 | E11: 210 | F11: 210 | G11: 220 | H11: =SUM(B11+C11+D11+E11+F11+G11) -> 1400 | I11: 200 | J11: 500
A12: 45931 | B12: 290 | C12: 220 | D12: 250 | E12: 210 | F12: 210 | G12: 220 | H12: =SUM(B12+C12+D12+E12+F12+G12) -> 1400 | I12: 200 | J12: 500
A13: 45962 | B13: 290 | C13: 220 | D13: 250 | E13: 210 | F13: 210 | G13: 220 | H13: =SUM(B13+C13+D13+E13+F13+G13) -> 1400 | I13: 200 | J13: 500
A14: 45992 | B14: 290 | C14: 220 | D14: 250 | E14: 210 | F14: 210 | G14: 220 | H14: =SUM(B14+C14+D14+E14+F14+G14) -> 1400 | I14: 200 | J14: 500
A19: Gesamt | B19: =SUM(B3+B4+B5+B6+B7+B8+B9+B10+B11+B12+B13+B14) -> 3480 | C19: =SUM(C3:C14) -> 2660 | D19: =SUM(D3:D14) -> 3000 | E19: =SUM(E3:E14) -> 2520 | F19: =SUM(F3:F14) -> 2520 | G19: =SUM(G3:G14) -> 2640 | H19: =SUM(H3:H14) -> 16820 | I19: =SUM(I3:I14) -> 2400 | J19: =SUM(J3:J14) -> 6000
A20: Ausgaben | B20: =VALUE('W107 Becker'!G37) -> 3593.0042 | C20: =VALUE('W207 Drost'!G37) -> 2695.0061 | D20: =VALUE('W307 Bernsee'!G37) -> 3183.6599 | E20: =VALUE('W407 Ballestriero'!G37) -> 2921.083 | F20: =VALUE('W507 Weber'!G37) -> 2597.5108 | G20: =VALUE('W607 Gneiting'!G37) -> 2540.3762 | H20: =SUM(B20:G20) -> 17530.64 | I20: Aktuell: | J20: 34940.85 | K20: 46101
A21: Differenz | B21: =SUM(B19-B20) -> -113.00415 | C21: =SUM(C19-C20) -> -35.006083 | D21: =SUM(D19-D20) -> -183.65987 | E21: =SUM(E19-E20) -> -401.08295 | F21: =SUM(F19-F20) -> -77.510755 | G21: =SUM(G19-G20) -> 99.623812 | H21: =SUM(B21:G21) -> -710.64
A23: Versicherungen | B23: Haftpflicht | C23: 60.45 | D23: Zahlung aus RL: | I23: Einnahmen | J23: =SUM(B19+C19+D19+E19+F19+G19) -> 16820
B24: Gebäude | C24: 1726.84 | I24: Ausgaben | J24: =VALUE(H20) -> 17530.64
B25: Summe: | C25: =SUM(C23+C24) -> 1787.29 | I25: Differenz | J25: =SUM(J23-J24) -> -710.64
I26: Rückzahlungen | J26: =SUM('W107 Becker'!G42+'W207 Drost'!G42+'W307 Bernsee'!G42+'W407 Ballestriero'!G42+'W507 Weber'!G42+'W607 Gneiting'!G43) -> -710.64
B29: Strom VaFa | C29: fairenergie Gas | D29: Schornstein | E29: Konto | F29: Müll | G29: Wasser | H29: Haus und Grund | I29: Baur | J29: Auslagen HM
A30: 45292 | B30: 39 | C30: 290 | G30: 442.07 | H30: 50
A31: 45323 | B31: =39+28.15+30.15 -> 97.3 | C31: 290 | I31: 304.95
A32: 45352 | B32: 39 | C32: 290 | E32: 44.65 | F32: 496.8
A33: 45383 | B33: 39 | C33: 290 | G33: 160.66
A34: 45413 | B34: 39 | C34: 290 | G34: 497.92
A35: 45444 | B35: 39 | C35: 290 | E35: 46.5
A36: 45474 | B36: 39 | C36: 290 | D36: 99.81 | G36: 497.92
A37: 45505 | B37: 39 | C37: 290
A38: 45536 | B38: 39 | C38: 290 | E38: 40.9
A39: 45566 | B39: 39 | C39: 290 | G39: 497.92
A40: 45597 | B40: 39 | C40: 290
A41: 45627 | B41: 39 | C41: 290 | E41: 40.9
A42: Summe: | B42: =SUM(B30:B41) -> 526.3 | C42: =SUM(C31:C41) -> 3190 | D42: =SUM(D30+D31+D32+D33+D34+D35+D36+D37+D38+D39+D40+D41) -> 99.81 | E42: =SUM(E30+E31+E32+E34+E35+E36+E37+E38+E39+E40+E41) -> 172.95 | F42: =SUM(F30+F31+F32+F33+F34+F35+F36+F37+F38+F39+F40+F41) -> 496.8 | G42: =SUM(G30+G31+G32+G33+G34+G35+G36+G37+G38+G39+G40+G41) -> 2096.49 | H42: =SUM(H30+H31+H37+H40+H32+H33+H34+H35+H36+H38+H39+H41) -> 50 | I42: =SUM(I30+I32+I31+I34+I39+I40+I41) -> 304.95 | J42: =SUM(J30:J41) -> 0

Sheet Becker
A1: Verteilung der Kosten | C1: Wohnung 1 | D1: Becker | E1: 2025
A3: Heizkosten | C3: Betrag | D3: Einheiten | E3: Preis je Einheit | F3: Verteilerschlüssel | G3: Einheit | H3: Summe
A4: 30% Grundkosten | C4: =SUM(Hauptabrechnung!C47) -> 948.6744 | D4: 414.52 | E4: =SUM(C4/D4) -> 2.2886095 | F4: 81.74 | G4: qm | H4: =SUM(E4*F4) -> 187.07094
A5: 70% Verbrauchskosten | C5: =SUM(Hauptabrechnung!C48) -> 2213.5736 | D5: =VALUE(Hauptabrechnung!D48) -> 17664.22 | E5: =SUM(C5/D5) -> 0.12531397 | F5: =VALUE(H27) -> 2694.034 | G5: Punkte | H5: =SUM(E5*F5) -> 337.6001
A7: Warmwasserkosten
A8: 30% Grundkosten | C8: =SUM(Hauptabrechnung!C51) -> 366.70127 | D8: 414.52 | E8: =SUM(C8/D8) -> 0.88464072 | F8: 81.74 | G8: qm | H8: =SUM(E8*F8) -> 72.310532
A9: 70% Verbrauchskosten | C9: =SUM(Hauptabrechnung!C52) -> 855.63629 | D9: =VALUE(Hauptabrechnung!D52) -> 75.512 | E9: =SUM(C9/D9) -> 11.33113 | F9: =VALUE(H31) -> 34.5 | G9: Kubikmeter | H9: =SUM(E9*F9) -> 390.92399
A11: Kaltwasserkosten | C11: =SUM(Hauptabrechnung!C54) -> 1307.9544 | D11: =VALUE(Hauptabrechnung!B15) -> 193.775 | E11: =SUM(C11/D11) -> 6.7498617 | F11: =VALUE(H36) -> 76.47 | G11: Kubikmeter | H11: =SUM(E11*F11) -> 516.16192
A12: _______________________________________________________________________________________________________
A13: Gesamt | C13: =SUM(C4:C11) -> 5692.54 | H13: =SUM(H4+H5+H8+H9+H11) -> 1504.0675
A14: Vorjahr | H14: =VALUE([1]Becker!$H$13) -> 1653.4812
A15: Differenz | H15: =SUM(H13-H14) -> -149.41369
A18: Heizkostenverteiler | B18: neu | C18: Datum | D18: Heizungstyp | E18: Faktor | G18: Ablesewert neu | H18: Verbrauch
A19: 90878776 | B19: Bad | D19: Typ22 900mm | E19: 1.717 | G19: =VALUE('Ablesung Becker'!F3) -> 123 | H19: =SUM(G19*E19) -> 211.191
A20: 90878777 | B20: Küche | D20: Typ21 600mm | E20: 0.882 | G20: =VALUE('Ablesung Becker'!F4) -> 0 | H20: =SUM(G20*E20) -> 0
A21: 90878834 | B21: Kinderzimmer | D21: Typ20 800mm | E21: 0.867 | F21: erneuert | G21: =VALUE('Ablesung Becker'!F5) -> 219 | H21: =SUM(G21*E21) -> 189.873
A22: 90878779 | B22: Kinderzimmer | D22: Typ20 800mm | E22: 0.867 | G22: =VALUE('Ablesung Becker'!F6) -> 81 | H22: =SUM(G22*E22) -> 70.227
A23: 90878835 | B23: Wohnen | D23: Typ22 900mm | E23: 2.289 | F23: erneuert | G23: =VALUE('Ablesung Becker'!F7) -> 920 | H23: =SUM(G23*E23) -> 2105.88
A24: 90878786 | B24: Wohnen | D24: Typ22 1000mm | E24: 1.717 | G24: =VALUE('Ablesung Becker'!F8) -> 14 | H24: =SUM(G24*E24) -> 24.038
A25: 90878787 | B25: Schlafen Kind | D25: Typ21 800mm | E25: 1.175 | G25: =VALUE('Ablesung Becker'!F9) -> 79 | H25: =SUM(G25*E25) -> 92.825
A26: 90878788 | B26: Schlafzimmer | D26: Typ33 700mm | E26: 1.782 | G26: =VALUE('Ablesung Becker'!F10) -> 0 | H26: =SUM(G26*E26) -> 0
G27: Summe: | H27: =SUM(H19:H25) -> 2694.034
A29: Warmwasserzähler | C29: Datum | D29: Typ | E29: Faktor | F29: Ablesewert alt | G29: Ablesewert neu | H29: Verbrauch
A30: 36946744 | B30: Bad | D30: Techem | E30: 1 | F30: =VALUE('Ablesung Becker'!E14) -> 225 | G30: =VALUE('Ablesung Becker'!F14) -> 259.5 | H30: =G30-F30 -> 34.5
G31: Summe: | H31: =SUM(H30) -> 34.5
A33: Kaltwasserzähler | C33: Datum | D33: Typ | E33: Faktor | F33: Ablesewert alt | G33: Ablesewert neu | H33: Verbrauch
A34: 37425700 | B34: Bad | D34: Techem | E34: 1 | F34: =VALUE('Ablesung Becker'!E16) -> 398.5 | G34: =VALUE('Ablesung Becker'!F16) -> 464.72 | H34: =G34-F34 -> 66.22
A35: 02235783 | B35: WK | D35: Techem | E35: 1 | F35: =VALUE('Ablesung Becker'!E17) -> 113 | G35: =VALUE('Ablesung Becker'!F17) -> 123.25 | H35: =G35-F35 -> 10.25
G36: Summe: | H36: =SUM(H34+H35) -> 76.47

Sheet W107 Becker
A1: Hausverwaltung Thomas Becker, Uhlandstr. 12, 72636 Frickenhausen
A3: Frau Tatiana Becker Herrn Thomas Becker Uhlandstr. 12 72636 Frickenhausen | G3: =TODAY() -> 46119
A4: Abrechnung 2025
A5: Wohnung Nr.1 Uhlandstr.12, Frickenhausen Abrechnung vom | F5: 01.01.2025 | G5: bis 31.12.2025
A6: _______________________________________________________________________________________________
A7: Bezeichnung | C7: Gesamt in € | D7: Gesamt | E7: Schlüsselbezeichnung | F7: Umlage | G7: Ihr Umlageanteil in €
D8: schlüssel | F8: schlüssel
A9: _______________________________________________________________________________________________
A10: Vergütung Techn. Hausbetr. | C10: =VALUE('Zahlungen 2025'!I19) -> 2400 | D10: 6 | E10: Wohneinheiten | F10: 1 | G10: =SUM(C10/D10*F10) -> 400
A12: Heizung Verbrauch | C12: =VALUE(Hauptabrechnung!$F$41) -> 5692.54 | E12: Abrechnung | F12: 1 | G12: =VALUE(Becker!$H$13) -> 1504.0675
A14: Heizung Wartung/Rep. | C14: =SUM(C15+C16+C17) -> 404.76 | D14: 6 | E14: Wohneinheiten | F14: 1 | G14: =SUM(C14/D14*F14) -> 67.46
A15: Schornsteinfeger | C15: =VALUE('Zahlungen 2025'!D42) -> 99.81
A16: Wartung Baur | C16: =VALUE('Zahlungen 2025'!I42) -> 304.95
A18: Allgemein Strom | C18: =VALUE('Zahlungen 2025'!B42) -> 526.3 | D18: 6 | E18: Wohneinheiten | F18: 1 | G18: =SUM(C18/D18*F18) -> 87.716667
A20: Müllgebühren | C20: =VALUE('Zahlungen 2025'!F42) -> 496.8 | D20: 10 | E20: Personen | F20: 4 | G20: =SUM(C20/D20*F20) -> 198.72
A24: Versicherungen | C24: =SUM(C25+C26) -> 1787.29 | D24: 6 | E24: Miteigent. Anteil | F24: 1 | G24: =SUM(C24/D24*F24) -> 297.88167
A25: Geb. mit Feuer | C25: =VALUE('Zahlungen 2025'!C24) -> 1726.84
A26: Haus-Haftpflicht | C26: =VALUE('Zahlungen 2025'!C23) -> 60.45
A29: Haus & Grund Mitgliedschaft | C29: =VALUE('Zahlungen 2025'!H42) -> 50 | D29: 6 | E29: Wohneinheiten | F29: 1 | G29: =C29/D29 -> 8.3333333
A31: Nebenkosten Geldverkehr | C31: =VALUE('Zahlungen 2025'!E42) -> 172.95 | D31: 6 | E31: Wohneinheiten | F31: 1 | G31: =SUM(C31/D31*F31) -> 28.825
A33: Reparaturen/Anschaffungen | C33: =VALUE('Zahlungen 2025'!J42) -> 0 | D33: 6 | E33: Wohneinheiten | F33: 1 | G33: =SUM(C33/D33*F33) -> 0
A35: Rücklagen 2023 | C35: =VALUE('Zahlungen 2025'!J19) -> 6000 | D35: 6 | E35: Wohneinheiten | F35: 1 | G35: =SUM(C35/D35*F35) -> 1000
A37: Gesamt | C37: =SUM(C10+C12+C35+C14+C18+C20+C24+C31+C33+C29) -> 17530.64 | G37: =SUM(G10+G12+G14+G18+G20+G29+G21+G24+G31+G33+G35) -> 3593.0042
A38: _______________________________________________________________________________________________
A40: Vorausszahlungen 2025 | G40: =VALUE('Zahlungen 2025'!B19) -> 3480
A41: _______________________________________________________________________________________________
A42: Differenzbetrag | E42: Ihre Nachzahlung beträgt: | G42: =SUM(G40-G37) -> -113.00415
A45: Bankverbindung: KSK Esslingen IBAN DE70 6115 0020 0008 1610 37
A46: weg.uhlandstr.12@gmx.de

Sheet Ablesung Becker
A1: Becker | B1: Ableseprotokoll Verbrauch 2025 | E1: Whg. 1
A2: Heizkostenverteiler | B2: Ort | C2: Heizungstyp | D2: Faktor | E2: Ablesewert alt | F2: Ablesewert
A3: 90878776 | B3: Bad | C3: Typ22 900mm | D3: 1.717 | E3: 111 | F3: 123
A4: 90878777 | B4: Küche | C4: Typ21 600mm | D4: 0.882 | E4: 0 | F4: 0
A5: 90878778 | B5: Kinderzimmer | C5: Typ20 800mm | D5: 0.867 | E5: 362 | F5: 219
A6: 90878779 | B6: Kinderzimmer | C6: Typ20 800mm | D6: 0.867 | E6: 5 | F6: 81
A7: 90878780 | B7: Wohnen | C7: Typ22 900mm | D7: 2.289 | E7: 607 | F7: 920
A8: 90878786 | B8: Wohnen | C8: Typ22 1000mm | D8: 1.717 | E8: 0 | F8: 14
A9: 90878787 | B9: Schlafen Kind | C9: Typ21 800mm | D9: 1.175 | E9: 159 | F9: 79
A10: 90878788 | B10: Schlafzimmer | C10: Typ33 700mm | D10: 1.782 | E10: 0 | F10: 0
D11: Summe:
A13: Warmwasserzähler | B13: Ort | E13: Ablesewert alt | F13: Ablesewert
A14: 60573438 | B14: Bad | C14: neu | E14: 225 | F14: 259.5
A15: Kaltwasserzähler | B15: Ort
A16: 84701228 | B16: Bad | C16: neu | E16: 398.5 | F16: 464.72
A17: 190117686 | B17: Waschmaschine | C17: neu | E17: 113 | F17: 123.25

Sheet Drost
A1: Verteilung der Kosten | C1: Wohnung 2 | D1: Drost | E1: 2025
A3: Heizkosten | C3: Betrag | D3: Einheiten | E3: Preis je Einheit | G3: Einheit | H3: Summe
A4: 30% Grundkosten | C4: =SUM(Hauptabrechnung!C47) -> 948.6744 | D4: 414.52 | E4: =SUM(C4/D4) -> 2.2886095 | F4: 58.77 | G4: qm | H4: =SUM(E4*F4) -> 134.50158
A5: 70% Verbrauchskosten | C5: =SUM(Hauptabrechnung!C48) -> 2213.5736 | D5: =VALUE(Hauptabrechnung!D48) -> 17664.22 | E5: =SUM(C5/D5) -> 0.12531397 | F5: =VALUE(H26) -> 3017.905 | G5: Punkte | H5: =SUM(E5*F5) -> 378.18567
A7: Warmwasserkosten
A8: 30% Grundkosten | C8: =SUM(Hauptabrechnung!F33*30%) -> 366.70127 | D8: 414.52 | E8: =SUM(C8/D8) -> 0.88464072 | F8: 58.77 | G8: qm | H8: =SUM(E8*F8) -> 51.990335
A9: 70% Verbrauchskosten | C9: =SUM(Hauptabrechnung!F33*70%) -> 855.63629 | D9: =VALUE(Hauptabrechnung!D52) -> 75.512 | E9: =SUM(C9/D9) -> 11.33113 | F9: =VALUE(H30) -> 2.077 | G9: Kubikmeter | H9: =SUM(E9*F9) -> 23.534757
A11: Kaltwasserkosten | C11: =SUM(Hauptabrechnung!C54) -> 1307.9544 | D11: =VALUE(Hauptabrechnung!B15) -> 193.775 | E11: =SUM(C11/D11) -> 6.7498617 | F11: =SUM(H35) -> 24.726 | G11: Kubikmeter | H11: =SUM(E11*F11) -> 166.89708
A12: _________________________________________________________________________________________________________________
A13: Gesamt | C13: =SUM(C4:C11) -> 5692.54 | H13: =SUM(H4+H5+H8+H9+H11) -> 755.10942
A14: Vorjahr | H14: 0
A15: Differenz | H15: =SUM(H13-H14) -> 755.10942
A18: Heizkostenverteiler | B18: neu | C18: Datum | D18: Heizungstyp | E18: Faktor | G18: Ablesewert neu | H18: Verbrauch
A19: 90878790 | B19: Flur | D19: Typ21 400mm | E19: 0.588 | G19: =VALUE('Ablesung Drost'!F3) -> 0 | H19: =SUM(G19*E19) -> 0
A20: 90878791 | B20: Wohnzimmer 1 | D20: Typ21 1200mm | E20: 1.764 | G20: =VALUE('Ablesung Drost'!F4) -> 995 | H20: =SUM(G20*E20) -> 1755.18
A21: 90878792 | B21: Wohnzimmer 2 | D21: Typ21 800mm | E21: 1.175 | G21: =VALUE('Ablesung Drost'!F5) -> 627 | H21: =SUM(G21*E21) -> 736.725
A22: 90878793 | B22: Wohnzimmer 3 | D22: Typ21 800mm | E22: 1.175 | G22: =VALUE('Ablesung Drost'!F6) -> 236 | H22: =SUM(G22*E22) -> 277.3
A23: 90878794 | B23: Küche | D23: Typ21 400mm | E23: 0.588 | G23: =VALUE('Ablesung Drost'!F7) -> 0 | H23: =SUM(G23*E23) -> 0
A24: 90878795 | B24: Bad | D24: Sondertyp 1700mm | E24: 1.23 | G24: =VALUE('Ablesung Drost'!F8) -> 201 | H24: =SUM(G24*E24) -> 247.23
A25: 90878796 | B25: Schlafzimmer | D25: Typ21 1000mm | E25: 1.47 | G25: =VALUE('Ablesung Drost'!F9) -> 1 | H25: =SUM(G25*E25) -> 1.47
G26: Summe: | H26: =SUM(H19:H25) -> 3017.905
A28: Warmwasserzähler | C28: Datum | D28: Typ | E28: Faktor | F28: Ablesewert alt | G28: Ablesewert neu | H28: Verbrauch
A29: 37032658 | B29: Bad | D29: Techem | E29: 1 | F29: =VALUE('Ablesung Drost'!E12) -> 31.9 | G29: =VALUE('Ablesung Drost'!F12) -> 33.977 | H29: =SUM(G29-F29) -> 2.077
G30: Summe: | H30: =SUM(H29) -> 2.077
A32: Kaltwasserzähler | C32: Datum | D32: Typ | E32: Faktor | F32: Ablesewert alt | G32: Ablesewert neu | H32: Verbrauch
A33: 37425656 | B33: Bad | D33: Techem | E33: 1 | F33: =VALUE('Ablesung Drost'!E14) -> 106.2 | G33: =VALUE('Ablesung Drost'!F14) -> 124.322 | H33: =SUM(G33-F33) -> 18.122
A34: 02234913 | B34: Waschmaschine | D34: Techem | E34: 1 | F34: =VALUE('Ablesung Drost'!E15) -> 10.4 | G34: =VALUE('Ablesung Drost'!F15) -> 17.004 | H34: =SUM(G34-F34) -> 6.604
G35: Summe: | H35: =SUM(H33+H34) -> 24.726

Sheet W207 Drost
A1: Hausverwaltung Thomas Becker, Uhlandstr. 12, 72636 Frickenhausen
A3: Sieglinde Drost Uhlandstr. 12 72636 Frickenhausen | G3: =TODAY() -> 46119
A4: Abrechnung 2025
A5: Wohnung Nr.2 Uhlandstr.12, Frickenhausen Abrechnung vom | E5: vom 01.01.2025 | G5: bis 31.12.2025
A6: _______________________________________________________________________________________________________
A7: Bezeichnung | C7: Gesamt in € | D7: Gesamt | E7: Schlüsselbezeichnung | G7: Ihr Umlageanteil in €
D8: schlüssel
A9: _______________________________________________________________________________________________________
A10: Vergütung Techn. Hausbetr. | C10: =VALUE('Zahlungen 2025'!I19) -> 2400 | D10: 6 | E10: Wohneinheiten | F10: 1 | G10: =SUM(C10/D10*F10) -> 400
A12: Heizung Verbrauch | C12: =VALUE(Hauptabrechnung!$F$41) -> 5692.54 | D12: 1 | F12: 1 | G12: =VALUE(Drost!H13) -> 755.10942
A14: Heizung Wartung/Rep. | C14: =SUM(C15+C16) -> 404.76 | D14: 6 | F14: 1 | G14: =SUM(C14/D14*F14) -> 67.46
A15: Schornsteinfeger | C15: =VALUE('Zahlungen 2025'!D42) -> 99.81
A16: Reparatur Baur | C16: =VALUE('Zahlungen 2025'!I42) -> 304.95
A18: Allgemein Strom | C18: =VALUE('Zahlungen 2025'!B42) -> 526.3 | D18: 6 | E18: Wohneinheiten | F18: 1 | G18: =SUM(C18/D18*F18) -> 87.716667
A20: Müllgebühren | C20: =VALUE('Zahlungen 2025'!F42) -> 496.8 | D20: 10 | E20: Personen | F20: 1 | G20: =SUM(C20/D20*F20) -> 49.68
A23: Versicherungen | C23: =SUM(C24+C25) -> 1787.29 | D23: 6 | E23: Miteigent. Anteil | F23: 1 | G23: =SUM(C23/D23*F23) -> 297.88167
A24: Geb. mit Feuer | C24: =VALUE('Zahlungen 2025'!C24) -> 1726.84
A25: Haus-Haftpflicht | C25: =VALUE('Zahlungen 2025'!C23) -> 60.45
A27: Haus & Grund Mitgliedschaft | C27: =VALUE('Zahlungen 2025'!H42) -> 50 | D27: 6 | E27: Wohneinheiten | F27: 1 | G27: =C27/D27 -> 8.3333333
A30: Nebenkosten Geldverkehr | C30: =VALUE('Zahlungen 2025'!E42) -> 172.95 | D30: 6 | E30: Wohneinheiten | F30: 1 | G30: =SUM(C30/D30*F30) -> 28.825
A33: Reparaturen/Anschaffungen | C33: =VALUE('Zahlungen 2025'!J42) -> 0 | D33: 6 | E33: Wohneinheiten | F33: 1 | G33: =SUM(C33/D33*F33) -> 0
A35: Rücklagen 2024 | C35: =VALUE('Zahlungen 2025'!J19) -> 6000 | D35: 6 | E35: Wohneinheiten | F35: 1 | G35: =SUM(C35/D35*F35) -> 1000
A37: Gesamt | C37: =SUM(C10+C12+C14+C18+C20+C23+C27+C30+C33+C35) -> 17530.64 | G37: =SUM(G10:G35) -> 2695.0061
A38: _______________________________________________________________________________________________________
A40: Vorausszahlungen 2025 | G40: =VALUE('Zahlungen 2025'!C19) -> 2660
A41: _______________________________________________________________________________________________________
A42: Differenzbetrag | E42: Ihre Nachzahlung beträgt: | G42: =SUM(G40-G37) -> -35.006083
A45: Bankverbindung: KSK Esslingen IBAN DE70 6115 0020 0008 1610 37
A46: weg.uhlandstr.12@gmx.de

Sheet Ablesung Drost
A1: Drost | B1: Ableseprotokoll Verbrauch 2025 | E1: Whg. 2
A2: Heizkostenverteiler | B2: Ort | C2: Heizungstyp | D2: Faktor | E2: Ablesewert alt | F2: Ablesewert
A3: 90878790 | B3: Flur | C3: Typ21 400mm | D3: 0.588 | E3: 0 | F3: 0
A4: 90878791 | B4: Wohnzimmer 1 | C4: Typ21 1200mm | D4: 1.764 | E4: 1089 | F4: 995
A5: 90878792 | B5: Wohnzimmer 2 | C5: Typ21 800mm | D5: 1.175 | E5: 898 | F5: 627
A6: 90878793 | B6: Wohnzimmer 3 | C6: Typ21 800mm | D6: 1.175 | E6: 0 | F6: 236
A7: 90878794 | B7: Küche | C7: Typ21 400mm | D7: 0.588 | E7: 0 | F7: 0
A8: 90878795 | B8: Bad | C8: Sondertyp 1700mm | D8: 1.23 | E8: 72 | F8: 201
A9: 90878796 | B9: Schlafzimmer | C9: Typ21 1000mm | D9: 1.47 | E9: 1 | F9: 1
A11: Warmwasserzähler | B11: Ort | E11: Ablesewert alt
A12: 60431049 | B12: Bad | C12: neu 2019 | E12: 31.9 | F12: 33.977
A13: Kaltwasserzähler | B13: Ort
A14: 84701243 | B14: Bad | C14: neu 2019 | E14: 106.2 | F14: 124.322
A15: 190117688 | B15: Waschmaschine | C15: neu 2019 | E15: 10.4 | F15: 17.004
E16: Summe. Kaltwasser
A17: Datum | B17: Unterschrift Abgelesener | D17: Unterschrift Ablesender

Sheet Bernsee
A1: Verteilung der Kosten | C1: Wohnung 3 | D1: Bernsee | E1: 2025
A3: Heizkosten | C3: Betrag | D3: Einheiten | E3: Preis je Einheit | F3: Verteilerschlüssel | G3: Einheit | H3: Summe
A4: 30% Grundkosten | C4: =SUM(Hauptabrechnung!F27*30%) -> 948.6744 | D4: 414.52 | E4: =SUM(C4/D4) -> 2.2886095 | F4: 69.13 | G4: qm | H4: =SUM(E4*F4) -> 158.21157
A5: 70% Verbrauchskosten | C5: =SUM(Hauptabrechnung!F27*70%) -> 2213.5736 | D5: =VALUE(Hauptabrechnung!D48) -> 17664.22 | E5: =SUM(C5/D5) -> 0.12531397 | F5: =VALUE(H28) -> 4982.496 | G5: Punkte | H5: =SUM(E5*F5) -> 624.37637
A7: Warmwasserkosten
A8: 30% Grundkosten | C8: =SUM(Hauptabrechnung!F33*30%) -> 366.70127 | D8: 414.52 | E8: =SUM(C8/D8) -> 0.88464072 | F8: 69.13 | G8: qm | H8: =SUM(E8*F8) -> 61.155213
A9: 70% Verbrauchskosten | C9: =SUM(Hauptabrechnung!F33*70%) -> 855.63629 | D9: =VALUE(Hauptabrechnung!D52) -> 75.512 | E9: =SUM(C9/D9) -> 11.33113 | F9: =VALUE(H32) -> 13.532 | G9: Kubikmeter | H9: =SUM(E9*F9) -> 153.33285
A11: Kaltwasserkosten | C11: =SUM(Hauptabrechnung!C54) -> 1307.9544 | D11: =VALUE(Hauptabrechnung!B15) -> 193.775 | E11: =SUM(C11/D11) -> 6.7498617 | F11: =VALUE(H37) -> 36.547 | G11: Kubikmeter | H11: =SUM(E11*F11) -> 246.68719
A12: _________________________________________________________________________________________________________
A13: Gesamt | C13: =SUM(C4:C11) -> 5692.54 | H13: =SUM(H4+H5+H8+H9+H11) -> 1243.7632
A14: Vorjahr | H14: =VALUE([1]Bernsee!$H$13) -> 1235.3246
A15: Differenz | H15: =SUM(H13-H14) -> 8.4385691
A19: Heizkostenverteiler | B19: neu | C19: Datum | D19: Heizungstyp | E19: Faktor | G19: Ablesewert neu | H19: Verbrauch
A20: 90878805 | B20: Flur | D20: Typ21 500mm | E20: 0.735 | G20: =VALUE('Ablesung Bernsee'!F3) -> 0 | H20: =SUM(E20*G20) -> 0
A21: 90878806 | B21: Bad | D21: Typ22 900mm | E21: 1.717 | G21: =VALUE('Ablesung Bernsee'!F4) -> 1818 | H21: =SUM(E21*G21) -> 3121.506
A22: 90878807 | B22: Zimmer 1 | D22: Typ20 700mm | E22: 0.758 | G22: =VALUE('Ablesung Bernsee'!F5) -> 0 | H22: =SUM(E22*G22) -> 0
A23: 90878808 | B23: Zimmer 2 | D23: Typ20 700mm | E23: 0.758 | G23: =VALUE('Ablesung Bernsee'!F6) -> 0 | H23: =SUM(E23*G23) -> 0
A24: 90878809 | B24: Küche | D24: Typ21 500mm | E24: 0.735 | G24: =VALUE('Ablesung Bernsee'!F7) -> 0 | H24: =SUM(E24*G24) -> 0
A25: 90878810 | B25: Wohnzimmer 1 | D25: Typ22 700mm | E25: 1.335 | G25: =VALUE('Ablesung Bernsee'!F8) -> 1394 | H25: =SUM(E25*G25) -> 1860.99
A26: 90878811 | B26: Wohnzimmer 2 | D26: Typ22 1000mm | E26: 1.908 | G26: =VALUE('Ablesung Bernsee'!F9) -> 0 | H26: =SUM(E26*G26) -> 0
A27: 90878812 | B27: Schlafzimmer | D27: Typ20 900mm | E27: 0.975 | G27: =VALUE('Ablesung Bernsee'!F10) -> 0 | H27: =SUM(E27*G27) -> 0
A28: Verbrauch | G28: Summe: | H28: =SUM(H20+H21+H22+H23+H24+H25+H26+H27) -> 4982.496
A30: Warmwasserzähler | C30: Datum | D30: Typ | E30: Faktor | F30: Ablesewert alt | G30: Ablesewert neu | H30: Verbrauch
A31: 36946751 | B31: B | D31: Techem | E31: 1 | F31: =VALUE('Ablesung Bernsee'!E13) -> 65 | G31: =VALUE('Ablesung Bernsee'!F13) -> 78.532 | H31: =SUM(G31-F31) -> 13.532
G32: Summe: | H32: =SUM(H31) -> 13.532
A34: Kaltwasserzähler | C34: Datum | D34: Typ | E34: Faktor | F34: Ablesewert alt | G34: Ablesewert neu | H34: Verbrauch
A35: 37425639 | B35: B | D35: Techem | E35: 1 | F35: =VALUE('Ablesung Bernsee'!E15) -> 160.7 | G35: =VALUE('Ablesung Bernsee'!F15) -> 190.977 | H35: =SUM(G35-F35) -> 30.277
A36: 02234948 | B36: WK | D36: Techem | E36: 1 | F36: =VALUE('Ablesung Bernsee'!E16) -> 61.2 | G36: =VALUE('Ablesung Bernsee'!F16) -> 67.47 | H36: =SUM(G36-F36) -> 6.27
G37: Summe: | H37: =SUM(H35+H36) -> 36.547

Sheet W307 Bernsee
A1: Hausverwaltung Thomas Becker, Uhlandstr. 12, 72636 Frickenhausen
A3: Frau Monika Bernsee Uhlandstr. 12 72636 Frickenhausen | G3: =TODAY() -> 46119
A4: Abrechnung 2025
A5: Wohnung Nr.3 Uhlandstr.12, Frickenhausen Abrechnung vom | F5: 01.01.2025 | G5: bis 31.12.2025
A6: _______________________________________________________________________________________________
A7: Bezeichnung | C7: Gesamt in € | D7: Gesamt | E7: Schlüsselbezeichnung | F7: Umlage | G7: Ihr Umlageanteil in €
D8: schlüssel | F8: schlüssel
A9: _______________________________________________________________________________________________
A10: Vergütung Techn. Hausbetr. | C10: =VALUE('Zahlungen 2025'!I19) -> 2400 | D10: 6 | E10: Wohneinheiten | F10: 1 | G10: =SUM(C10/D10*F10) -> 400
A12: Heizung Verbrauch | C12: =VALUE(Hauptabrechnung!$F$41) -> 5692.54 | D12: 1 | E12: Abrechnung | F12: 1 | G12: =VALUE(Bernsee!$H$13) -> 1243.7632
A14: Heizung Wartung/Rep. | C14: =SUM(C15+C16+C17) -> 404.76 | D14: 6 | E14: Wohneinheiten | F14: 1 | G14: =SUM(C14/D14*F14) -> 67.46
A15: Schornsteinfeger | C15: =VALUE('Zahlungen 2025'!D42) -> 99.81
A16: Wartung Baur | C16: =VALUE('Zahlungen 2025'!I42) -> 304.95
A18: Allgemein Strom | C18: =VALUE('Zahlungen 2025'!B42) -> 526.3 | D18: 6 | E18: Wohneinheiten | F18: 1 | G18: =SUM(C18/D18*F18) -> 87.716667
A20: Müllgebühren | C20: =VALUE('Zahlungen 2025'!F42) -> 496.8 | D20: 10 | E20: Personen | F20: 1 | G20: =SUM(C20/D20*F20) -> 49.68
A25: Versicherungen | C25: =SUM(C26+C27) -> 1787.29 | D25: 6 | E25: Miteigent. Anteil | F25: 1 | G25: =SUM(C25/D25*F25) -> 297.88167
A26: Geb. mit Feuer | C26: =VALUE('Zahlungen 2025'!C24) -> 1726.84
A27: Haus-Haftpflicht | C27: =VALUE('Zahlungen 2025'!C23) -> 60.45
A29: Haus & Grund Mitgliedschaft | C29: =VALUE('Zahlungen 2025'!H42) -> 50 | D29: 6 | E29: Wohneinheiten | F29: 1 | G29: =C29/D29 -> 8.3333333
A31: Nebenkosten Geldverkehr | C31: =VALUE('Zahlungen 2025'!E42) -> 172.95 | D31: 6 | E31: Wohneinheiten | F31: 1 | G31: =SUM(C31/D31*F31) -> 28.825
A33: Reparaturen/Anschaffungen | C33: =VALUE('Zahlungen 2025'!J42) -> 0 | D33: 6 | E33: Wohneinheiten | F33: 1 | G33: =SUM(C33/D33*F33) -> 0
A35: Rücklagen 2024 | C35: =VALUE('Zahlungen 2025'!J19) -> 6000 | D35: 6 | E35: Wohneinheiten | F35: 1 | G35: =SUM(C35/D35*F35) -> 1000
A37: Gesamt | C37: =SUM(C10+C12+C35+C14+C18+C20+C25+C29+C31+C33) -> 17530.64 | G37: =SUM(G10:G35) -> 3183.6599
A38: _______________________________________________________________________________________________
A40: Vorausszahlungen 2025 | G40: =VALUE('Zahlungen 2025'!D19) -> 3000
A41: _______________________________________________________________________________________________
A42: Differenzbetrag | E42: Ihre Nachzahlung beträgt: | G42: =SUM(G40-G37) -> -183.65987
A45: Bankverbindung: KSK Esslingen IBAN DE70 6115 0020 0008 1610 37
A46: weg.uhlandstr.12@gmx.de

Sheet Ablesung Bernsee
A1: Bernsee | B1: Ableseprotokoll Verbrauch 2025 | E1: Whg. 3
A2: Heizkostenverteiler | B2: Ort | C2: Heizungstyp | D2: Faktor | E2: Ablesewert alt | F2: Ablesewert
A3: 90878805 | B3: Flur | C3: Typ21 500mm | D3: 0.735 | E3: 0 | F3: 0
A4: 90878806 | B4: Bad | C4: Typ22 900mm | D4: 1.717 | E4: 1845 | F4: 1818
A5: 90878807 | B5: Zimmer 1 | C5: Typ20 700mm | D5: 0.758 | E5: 0 | F5: 0
A6: 90878808 | B6: Zimmer 2 | C6: Typ20 700mm | D6: 0.758 | E6: 0 | F6: 0
A7: 90878809 | B7: Küche | C7: Typ21 500mm | D7: 0.735 | E7: 0 | F7: 0
A8: 90878810 | B8: Wohnzimmer 1 | C8: Typ22 700mm | D8: 1.335 | E8: 1478 | F8: 1394
A9: 90878811 | B9: Wohnzimmer 2 | C9: Typ22 1000mm | D9: 1.908 | E9: 2 | F9: 0
A10: 90878812 | B10: Schlafzimmer | C10: Typ20 900mm | D10: 0.975 | E10: 0 | F10: 0
A12: Warmwasserzähler | B12: Ort | E12: Ablesewert alt
A13: 60431046 | B13: Bad | C13: neu | E13: 65 | F13: 78.532
A14: Kaltwasserzähler | B14: Ort
A15: 84701241 | B15: Bad | C15: neu | E15: 160.7 | F15: 190.977
A16: 190117687 | B16: Waschmaschine | C16: neu | E16: 61.2 | F16: 67.47
A17: Datum | B17: Unterschrift Abgelesener | D17: Unterschrift Ablesender

Sheet Ballestriero
A1: Verteilung der Kosten | C1: Wohnung 4 | D1: Ballestriero | E1: 2025
A3: Heizkosten | C3: Betrag | D3: Einheiten | E3: Preis je Einheit | F3: Verteilerschlüssel | G3: Einheit | H3: Summe
A4: 30% Grundkosten | C4: =SUM(Hauptabrechnung!F27*30%) -> 948.6744 | D4: 414.52 | E4: =SUM(C4/D4) -> 2.2886095 | F4: 73.87 | G4: qm | H4: =SUM(E4*F4) -> 169.05958
A5: 70% Verbrauchskosten | C5: =SUM(Hauptabrechnung!F27*70%) -> 2213.5736 | D5: =VALUE(Hauptabrechnung!D48) -> 17664.22 | E5: =SUM(C5/D5) -> 0.12531397 | F5: =VALUE(H28) -> 3339.538 | G5: Punkte | H5: =SUM(E5*F5) -> 418.49078
A7: Warmwasserkosten
A8: 30% Grundkosten | C8: =SUM(Hauptabrechnung!F33*30%) -> 366.70127 | D8: 414.52 | E8: =SUM(C8/D8) -> 0.88464072 | F8: 73.87 | G8: qm | H8: =SUM(E8*F8) -> 65.34841
A9: 70% Verbrauchskosten | C9: =SUM(Hauptabrechnung!F33*70%) -> 855.63629 | D9: =VALUE(Hauptabrechnung!D52) -> 75.512 | E9: =SUM(C9/D9) -> 11.33113 | F9: =VALUE(H32) -> 8.382 | G9: Kubikmeter | H9: =SUM(E9*F9) -> 94.977532
A11: Kaltwasserkosten | C11: =SUM(Hauptabrechnung!C54) -> 1307.9544 | D11: =VALUE(Hauptabrechnung!B15) -> 193.775 | E11: =SUM(C11/D11) -> 6.7498617 | F11: =VALUE(H37) -> 27.205 | G11: Kubikmeter | H11: =SUM(E11*F11) -> 183.62999
A12: __________________________________________________________________________________________________________________________________
A13: Gesamt | C13: =SUM(C4:C11) -> 5692.54 | H13: =SUM(H4+H5+H8+H9+H11) -> 931.50629
A14: Vorjahr | H14: =VALUE([1]Ballestriero!$H$13) -> 953.19878
A15: Differenz | H15: =SUM(H13-H14) -> -21.692494
A19: Heizkostenverteiler | C19: Datum | D19: Heizungstyp | E19: Faktor | G19: Ablesewert neu | H19: Verbrauch
A20: 90878797 | B20: Flur | D20: Typ21 500mm | E20: 0.735 | G20: =VALUE('Ablesung Ballestriero'!F3) -> 1660 | H20: =SUM(E20*G20) -> 1220.1
A21: 90878798 | B21: Zimmer 1 | D21: Typ33 500mm | E21: 1.273 | G21: =VALUE('Ablesung Ballestriero'!F4) -> 0 | H21: =SUM(E21*G21) -> 0
A22: 90878799 | B22: Wohnzimmer 1 | D22: Typ33 1200mmx330 | E22: 2.016 | G22: =VALUE('Ablesung Ballestriero'!F5) -> 680 | H22: =SUM(E22*G22) -> 1370.88
A23: 90878800 | B23: Wohnzimmer 2 | D23: Typ21 700mmx330 | E23: 0.679 | G23: =VALUE('Ablesung Ballestriero'!F6) -> 0 | H23: =SUM(E23*G23) -> 0
A24: 90878801 | B24: Wohnzimmer 3 | D24: Typ22 1100mm | E24: 2.098 | G24: =VALUE('Ablesung Ballestriero'!F7) -> 142 | H24: =SUM(E24*G24) -> 297.916
A25: 90878802 | B25: Küche | D25: Typ22 500mm | E25: 0.954 | G25: =VALUE('Ablesung Ballestriero'!F8) -> 0 | H25: =SUM(E25*G25) -> 0
A26: 90878803 | B26: Bad | D26: Typ33 500mm | E26: 1.273 | G26: =VALUE('Ablesung Ballestriero'!F9) -> 354 | H26: =SUM(E26*G26) -> 450.642
A27: 90878804 | B27: Schlafzimmer | D27: Typ22 700mm | E27: 1.335 | G27: =VALUE('Ablesung Ballestriero'!F10) -> 0 | H27: =SUM(E27*G27) -> 0
A28: Verbrauch | G28: Summe: | H28: =SUM(H20+H21+H22+H23+H24+H25+H26+H27) -> 3339.538
A30: Warmwasserzähler | C30: Datum | D30: Typ | E30: Faktor | F30: Ablesewert alt | G30: Ablesewert neu | H30: Verbrauch
A31: 36946730 | B31: B | D31: Techem | E31: 1 | F31: =VALUE('Ablesung Ballestriero'!E13) -> 41.2 | G31: =VALUE('Ablesung Ballestriero'!F13) -> 49.582 | H31: =SUM(G31-F31) -> 8.382
G32: Summe: | H32: =SUM(H31) -> 8.382
A34: Kaltwasserzähler | C34: Datum | D34: Typ | E34: Faktor | F34: Ablesewert alt | G34: Ablesewert neu | H34: Verbrauch
A35: 37425693 | B35: B | D35: Techem | E35: 1 | F35: =VALUE('Ablesung Ballestriero'!E15) -> 150.4 | G35: =VALUE('Ablesung Ballestriero'!F15) -> 176.123 | H35: =SUM(G35-F35) -> 25.723
A36: 02234937 | B36: WK | D36: Techem | E36: 1 | F36: =VALUE('Ablesung Ballestriero'!E16) -> 12.5 | G36: =VALUE('Ablesung Ballestriero'!F16) -> 13.982 | H36: =SUM(G36-F36) -> 1.482
G37: Summe: | H37: =SUM(H35+H36) -> 27.205

Sheet W407 Ballestriero
A1: Hausverwaltung Thomas Becker, Uhlandstr. 12, 72636 Frickenhausen
A3: Frau S. Ballestriero Herrn U. Ballestriero Robert-Koch Str. 17 72636 Tischardt | G3: =TODAY() -> 46119
A4: Abrechnung 2025
A5: Wohnung Nr.4 Uhlandstr.12, Frickenhausen Abrechnung vom | F5: 01.01.2025 | G5: bis 31.12.2025
A6: ____________________________________________________________________________________________________
A7: Bezeichnung | C7: Gesamt in € | D7: Gesamt | E7: Schlüsselbezeichnung | F7: Umlage | G7: Ihr Umlageanteil in €
D8: schlüssel | F8: schlüssel
A9: ____________________________________________________________________________________________________
A10: Vergütung Techn. Hausbetr. | C10: =VALUE('Zahlungen 2025'!I19) -> 2400 | D10: 6 | E10: Wohneinheiten | F10: 1 | G10: =SUM(C10/D10*F10) -> 400
A12: Heizung Verbrauch | C12: =VALUE(Hauptabrechnung!$F$41) -> 5692.54 | D12: 1 | E12: Abrechnung | F12: 1 | G12: =VALUE(Ballestriero!$H$13) -> 931.50629
A14: Heizung Wartung/Rep. | C14: =SUM(C15+C16+C17) -> 404.76 | D14: 6 | E14: Wohneinheiten | F14: 1 | G14: =SUM(C14/D14*F14) -> 67.46
A15: Schornsteinfeger | C15: =VALUE('Zahlungen 2025'!D42) -> 99.81
A16: Wartung Baur | C16: =VALUE('Zahlungen 2025'!I42) -> 304.95
A18: Allgemein Strom | C18: =VALUE('Zahlungen 2025'!B42) -> 526.3 | D18: 6 | E18: Wohneinheiten | F18: 1 | G18: =SUM(C18/D18*F18) -> 87.716667
A20: Müllgebühren | C20: =VALUE('Zahlungen 2025'!F42) -> 496.8 | D20: 10 | E20: Personen | F20: 2 | G20: =SUM(C20/D20*F20) -> 99.36
A25: Versicherungen | C25: =SUM(C26+C27) -> 1787.29 | D25: 6 | E25: Miteigent. Anteil | F25: 1 | G25: =SUM(C25/D25*F25) -> 297.88167
A26: Geb. mit Feuer | C26: =VALUE('Zahlungen 2025'!C24) -> 1726.84
A27: Haus-Haftpflicht | C27: =VALUE('Zahlungen 2025'!C23) -> 60.45
A29: Haus & Grund Mitgliedschaft | C29: =VALUE('Zahlungen 2025'!H42) -> 50 | D29: 6 | E29: Wohneinheiten | F29: 1 | G29: =C29/D29 -> 8.3333333
A31: Reparaturen/Anschaffungen | C31: =VALUE('Zahlungen 2025'!J42) -> 0 | D31: 6 | E31: Wohneinheiten | F31: 1 | G31: =SUM(C31/D31*F31) -> 0
A33: Nebenkosten Geldverkehr | C33: =VALUE('Zahlungen 2025'!E42) -> 172.95 | D33: 6 | E33: Wohneinheiten | F33: 1 | G33: =SUM(C33/D33*F33) -> 28.825
A35: Rücklagen 2024 | C35: =VALUE('Zahlungen 2025'!J19) -> 6000 | D35: 6 | E35: Wohneinheiten | F35: 1 | G35: =SUM(C35/D35*F35) -> 1000
A37: Gesamt | C37: =SUM(C10+C12+C35+C14+C18+C20+C25+C29+C31+C33) -> 17530.64 | G37: =SUM(G10+G12+G14+G18+G20+G21+G22+G25+G29+G31+G33+G35) -> 2921.083
A38: _______________________________________________________________________________________________
A40: Vorausszahlungen 2025 | G40: =VALUE('Zahlungen 2025'!E19) -> 2520
A41: _______________________________________________________________________________________________
A42: Differenzbetrag | E42: Ihre Nachzahlung beträgt: | G42: =SUM(G40-G37) -> -401.08295
A45: Bankverbindung: KSK Esslingen IBAN DE70 6115 0020 0008 1610 37
A46: weg.uhlandstr.12@gmx.de

Sheet Ablesung Ballestriero
A1: Ballestriero | B1: Ableseprotokoll Verbrauch 2025 | E1: Whg. 4
A2: Heizkostenverteiler | B2: Ort | C2: Heizungstyp | D2: Faktor | E2: Ablesewert alt | F2: Ablesewert
A3: 90878797 | B3: Flur | C3: Typ21 500mm | D3: 0.735 | E3: 1452 | F3: 1660
A4: 90878798 | B4: Zimmer 1 | C4: Typ33 500mm | D4: 1.273 | E4: 0 | F4: 0
A5: 90878799 | B5: Wohnzimmer 1 | C5: Typ33 1200mm | D5: 2.016 | E5: 900 | F5: 680
A6: 90878800 | B6: Wohnzimmer 2 | C6: Typ21 700mm | D6: 0.679 | E6: 0 | F6: 0
A7: 90878801 | B7: Wohnzimmer 3 | C7: Typ22 1100mm | D7: 2.098 | E7: 4 | F7: 142
A8: 90878802 | B8: Küche | C8: Typ22 500mm | D8: 0.954 | E8: 0 | F8: 0
A9: Neu 90878832 alter war defekt | B9: Bad | C9: Typ33 500mm | D9: 1.273 | E9: 438 | F9: 354
A10: 90878804 | B10: Schlafzimmer | C10: Typ22 700mm | D10: 1.335 | E10: 0 | F10: 0
A12: Warmwasserzähler | B12: Ort | E12: Ablesewert alt
A13: 60431051 | B13: Bad | C13: neu | E13: 41.2 | F13: 49.582
A14: Kaltwasserzähler | B14: Ort
A15: 84701231 | B15: Bad | C15: neu | E15: 150.4 | F15: 176.123
A16: 190117690 | B16: Waschmaschine | C16: neu | E16: 12.5 | F16: 13.982
A17: Datum | B17: Unterschrift Abgelesener | D17: Unterschrift Ablesender

Sheet Weber
A1: Verteilung der Kosten | C1: Wohnung 5 | D1: Weber | E1: 2025
A3: Heizkosten | C3: Betrag | D3: Einheiten | E3: Preis je Einheit | F3: Verteilerschlüssel | G3: Einheit | H3: Summe
A4: 30% Grundkosten | C4: =SUM(Hauptabrechnung!F27*30%) -> 948.6744 | D4: 414.52 | E4: =SUM(C4/D4) -> 2.2886095 | F4: 46.69 | G4: qm | H4: =SUM(E4*F4) -> 106.85518
A5: 70% Verbrauchskosten | C5: =SUM(Hauptabrechnung!F27*70%) -> 2213.5736 | D5: =VALUE(Hauptabrechnung!D48) -> 17664.22 | E5: =SUM(C5/D5) -> 0.12531397 | F5: =VALUE(H27) -> 2095.92 | G5: Punkte | H5: =SUM(E5*F5) -> 262.64806
A7: Warmwasserkosten
A8: 30% Grundkosten | C8: =SUM(Hauptabrechnung!F33*30%) -> 366.70127 | D8: 414.52 | E8: =SUM(C8/D8) -> 0.88464072 | F8: 46.69 | G8: qm | H8: =SUM(E8*F8) -> 41.303875
A9: 70% Verbrauchskosten | C9: =SUM(Hauptabrechnung!F33*70%) -> 855.63629 | D9: =VALUE(Hauptabrechnung!D52) -> 75.512 | E9: =SUM(C9/D9) -> 11.33113 | F9: =VALUE(H31) -> 12.921 | G9: Kubikmeter | H9: =SUM(E9*F9) -> 146.40953
A11: Kaltwasserkosten | C11: =SUM(Hauptabrechnung!C54) -> 1307.9544 | D11: =VALUE(Hauptabrechnung!B15) -> 193.775 | E11: =SUM(C11/D11) -> 6.7498617 | F11: =VALUE(H36) -> 14.874 | G11: Kubikmeter | H11: =SUM(E11*F11) -> 100.39744
A12: _____________________________________________________________________________________________________________
A13: Gesamt | C13: =SUM(C4:C11) -> 5692.54 | H13: =SUM(H4+H5+H8+H9+H11) -> 657.61409
A14: Vorjahr | H14: =VALUE([1]Weber!$H$13) -> 624.97668
A15: Differenz | H15: =SUM(H13-H14) -> 32.637412
A19: Heizkostenverteiler | C19: Datum | D19: Heizungstyp | E19: Faktor | G19: Ablesewert neu | H19: Verbrauch
A20: 90878819 | B20: Flur | D20: Typ21 500mm | E20: 0.735 | G20: =VALUE('Ablesung Weber'!F3) -> 571 | H20: =SUM(E20*G20) -> 419.685
A21: 90878813 | B21: Bad | D21: Typ33 500mm | E21: 1.273 | G21: =VALUE('Ablesung Weber'!F4) -> 1 | H21: =SUM(E21*G21) -> 1.273
A22: 90878814 | B22: Küche | D22: Typ22 500mm | E22: 0.954 | G22: =VALUE('Ablesung Weber'!F5) -> 0 | H22: =SUM(E22*G22) -> 0
A23: 90878815 | B23: Wohnzimmer 1 | D23: Typ33 1200mm | E23: 3.055 | G23: =VALUE('Ablesung Weber'!F6) -> 294 | H23: =SUM(E23*G23) -> 898.17
A24: 90878816 | B24: Wohnzimmer 2 | D24: Typ21 700mm | E24: 1.029 | G24: =VALUE('Ablesung Weber'!F7) -> 2 | H24: =SUM(E24*G24) -> 2.058
A25: 90878817 | B25: Wohnzimmer 3 | D25: Typ22 1100mm | E25: 2.098 | G25: =VALUE('Ablesung Weber'!F8) -> 368 | H25: =SUM(E25*G25) -> 772.064
A26: 90878818 | B26: Schlafzimmer | D26: Typ22 700mm | E26: 1.335 | G26: =VALUE('Ablesung Weber'!F9) -> 2 | H26: =SUM(E26*G26) -> 2.67
G27: Summe: | H27: =SUM(H20:H26) -> 2095.92
A29: Warmwasserzähler | C29: Datum | D29: Typ | E29: Faktor | F29: Ablesewert alt | G29: Ablesewert neu | H29: Verbrauch
A30: 36946720 | B30: Bad | D30: Techem | E30: 1 | F30: =VALUE('Ablesung Weber'!E12) -> 49.8 | G30: =VALUE('Ablesung Weber'!F12) -> 62.721 | H30: =SUM(G30-F30) -> 12.921
G31: Summe: | H31: =SUM(H30) -> 12.921
A33: Kaltwasserzähler | C33: Datum | D33: Typ | E33: Faktor | F33: Ablesewert alt | G33: Ablesewert neu | H33: Verbrauch
A34: 37425696 | B34: Bad | D34: Techem | E34: 1 | F34: =VALUE('Ablesung Weber'!E14) -> 69.3 | G34: =VALUE('Ablesung Weber'!F14) -> 82.474 | H34: =SUM(G34-F34) -> 13.174
A35: 02235011 | B35: Waschmaschine | D35: Techem | E35: 1 | F35: =VALUE('Ablesung Weber'!E15) -> 9.2 | G35: =VALUE('Ablesung Weber'!F15) -> 10.9 | H35: =SUM(G35-F35) -> 1.7
G36: Summe: | H36: =SUM(H34+H35) -> 14.874

Sheet W507 Weber
A1: Hausverwaltung Thomas Becker, Uhlandstr. 12, 72636 Frickenhausen
A3: Michael Weber Uhlandstr. 12 72636 Frickenhausen | G3: =TODAY() -> 46119
A4: Abrechnung 2025
A5: Wohnung Nr.5 Uhlandstr.12, Frickenhausen Abrechnung vom | F5: 01.01.2025 | G5: bis 31.12.2025
A6: _______________________________________________________________________________________________
A7: Bezeichnung | C7: Gesamt in € | D7: Gesamt | E7: Schlüsselbezeichnung | F7: Umlage | G7: Ihr Umlageanteil in €
D8: schlüssel | F8: schlüssel
A9: _______________________________________________________________________________________________
A10: Vergütung Techn. Hausbetr. | C10: =VALUE('Zahlungen 2025'!I19) -> 2400 | D10: 6 | E10: Wohneinheiten | F10: 1 | G10: =SUM(C10/D10*F10) -> 400
A12: Heizung Verbrauch | C12: =VALUE(Hauptabrechnung!$F$41) -> 5692.54 | D12: 1 | E12: Abrechnung | F12: 1 | G12: =VALUE(Weber!H13) -> 657.61409
A14: Heizung Wartung/Rep. | C14: =SUM(C15+C16+C17) -> 404.76 | D14: 6 | E14: Wohneinheiten | F14: 1 | G14: =SUM(C14/D14*F14) -> 67.46
A15: Schornsteinfeger | C15: =VALUE('Zahlungen 2025'!D42) -> 99.81
A16: Wartung Baur | C16: =VALUE('Zahlungen 2025'!I42) -> 304.95
A18: Allgemein Strom | C18: =VALUE('Zahlungen 2025'!B42) -> 526.3 | D18: 6 | E18: Wohneinheiten | F18: 1 | G18: =SUM(C18/D18*F18) -> 87.716667
A20: Müllgebühren | C20: =VALUE('Zahlungen 2025'!F42) -> 496.8 | D20: 10 | E20: Personen | F20: 1 | G20: =SUM(C20/D20*F20) -> 49.68
A25: Versicherungen | C25: =SUM(C26+C27) -> 1787.29 | D25: 6 | E25: Miteigent. Anteil | F25: 1 | G25: =SUM(C25/D25*F25) -> 297.88167
A26: Geb. mit Feuer | C26: =VALUE('Zahlungen 2025'!C24) -> 1726.84
A27: Haus-Haftpflicht | C27: =VALUE('Zahlungen 2025'!C23) -> 60.45
A29: Haus & Grund Mitgliedschaft | C29: =VALUE('Zahlungen 2025'!H42) -> 50 | D29: 6 | E29: Wohneinheiten | F29: 1 | G29: =C29/D29 -> 8.3333333
A31: Nebenkosten Geldverkehr | C31: =VALUE('Zahlungen 2025'!E42) -> 172.95 | D31: 6 | E31: Wohneinheiten | F31: 1 | G31: =C31/D31 -> 28.825
A33: Reparaturen/Anschaffungen | C33: =VALUE('Zahlungen 2025'!J42) -> 0 | D33: 6 | E33: Wohneinheiten | F33: 1 | G33: =SUM(C33/D33*F33) -> 0
A35: Rücklagen 2024 | C35: =VALUE('Zahlungen 2025'!J19) -> 6000 | D35: 6 | E35: Wohneinheiten | F35: 1 | G35: =SUM(C35/D35*F35) -> 1000
A37: Gesamt | C37: =SUM(C10+C12+C35+C14+C18+C20+C25+C29+C31+C33) -> 17530.64 | G37: =SUM(G10+G12+G14+G18+G20+G21+G22+G25+G29+G31+G33+G35) -> 2597.5108
A38: _______________________________________________________________________________________________
A40: Vorausszahlungen 2025 | G40: =VALUE('Zahlungen 2025'!F19) -> 2520
A41: _______________________________________________________________________________________________
A42: Differenzbetrag | E42: Ihre Rückzahlung beträgt: | G42: =SUM(G40-G37) -> -77.510755
A45: Bankverbindung: KSK Esslingen IBAN DE70 6115 0020 0008 1610 37
A46: weg.uhlandstr.12@gmx.de

Sheet Ablesung Weber
A1: Weber | B1: Ableseprotokoll Verbrauch 2025 | E1: Whg. 5
A2: Heizkostenverteiler | B2: Ort | C2: Heizungstyp | D2: Faktor | E2: Ablesewert alt | F2: Ablesewert
A3: 90878819 | B3: Flur | C3: Typ21 500mm | D3: 0.735 | E3: 214 | F3: 571
A4: 90878813 | B4: Bad | C4: Typ33 500mm | D4: 1.273 | E4: 20 | F4: 1
A5: 90878814 | B5: Küche | C5: Typ22 500mm | D5: 0.954 | E5: 0 | F5: 0
A6: 90878815 | B6: Wohnzimmer 1 | C6: Typ33 1200mm | D6: 3.055 | E6: 353 | F6: 294
A7: 90878816 | B7: Wohnzimmer 2 | C7: Typ21 700mm | D7: 1.029 | E7: 0 | F7: 2
A8: 90878817 | B8: Wohnzimmer 3 | C8: Typ22 1100mm | D8: 2.098 | E8: 385 | F8: 368
A9: 90878818 | B9: Schlafzimmer | C9: Typ22 700mm | D9: 1.335 | E9: 0 | F9: 2
A11: Warmwasserzähler | B11: Ort | E11: Ablesewert alt
A12: 60431075 | B12: Bad | C12: neu | E12: 49.8 | F12: 62.721
A13: Kaltwasserzähler | B13: Ort
A14: 84701238 | B14: Bad | C14: neu | E14: 69.3 | F14: 82.474
A15: 190117700 | B15: Waschmaschine | C15: neu | E15: 9.2 | F15: 10.9
A17: Datum | B17: Unterschrift Abgelesener | D17: Unterschrift Ablesender
B18: Becker

Sheet Gneiting
A1: Verteilung der Kosten | C1: Wohnung 6 | D1: Gneiting | E1: 2025
A3: Heizkosten | C3: Betrag | D3: Einheiten | E3: Preis je Einheit | F3: Verteilerschlüssel | G3: Einheit | H3: Summe
A4: 30% Grundkosten | C4: =SUM(Hauptabrechnung!F27*30%) -> 948.6744 | D4: 414.52 | E4: =SUM(C4/D4) -> 2.2886095 | F4: 84.32 | G4: qm | H4: =SUM(E4*F4) -> 192.97555
A5: 70% Verbrauchskosten | C5: =SUM(Hauptabrechnung!F27*70%) -> 2213.5736 | D5: =VALUE(Hauptabrechnung!D48) -> 17664.22 | E5: =SUM(C5/D5) -> 0.12531397 | F5: =VALUE(H32) -> 1534.327 | G5: Punkte | H5: =SUM(E5*F5) -> 192.27261
A7: Warmwasserkosten
A8: 30% Grundkosten | C8: =SUM(Hauptabrechnung!F33*30%) -> 366.70127 | D8: 414.52 | E8: =SUM(C8/D8) -> 0.88464072 | F8: 84.32 | G8: qm | H8: =SUM(E8*F8) -> 74.592905
A9: 70% Verbrauchskosten | C9: =SUM(Hauptabrechnung!F33*70%) -> 855.63629 | D9: =VALUE(Hauptabrechnung!D52) -> 75.512 | E9: =SUM(C9/D9) -> 11.33113 | F9: =VALUE(H37) -> 4.1 | G9: Kubikmeter | H9: =SUM(E9*F9) -> 46.457633
A11: Kaltwasserkosten | C11: =SUM(Hauptabrechnung!C54) -> 1307.9544 | D11: =VALUE(Hauptabrechnung!B15) -> 193.775 | E11: =SUM(C11/D11) -> 6.7498617 | F11: =VALUE(H43) -> 13.953 | G11: Kubikmeter | H11: =SUM(E11*F11) -> 94.18082
A12: _________________________________________________________________________________________________________________
A13: Gesamt | C13: =SUM(C4+C5+C8+C9+C11) -> 5692.54 | H13: =SUM(H4+H5+H8+H9+H11) -> 600.47952
A14: Vorjahr | H14: =VALUE([1]Gneiting!$H$13) -> 590.81626
A15: Differenz | H15: =SUM(H13-H14) -> 9.663265
A19: Heizkostenverteiler | C19: Datum | D19: Heizungstyp | E19: Faktor | G19: Ablesewert neu | H19: Verbrauch
A20: 90878820 | B20: Flur | D20: Typ22 600mm | E20: 1.144 | G20: =VALUE('Ablesung Gneiting'!F3) -> 0 | H20: =SUM(G20*E20) -> 0
A21: 90878821 | B21: Küche | D21: Typ22 500mm | E21: 0.954 | G21: =VALUE('Ablesung Gneiting'!F4) -> 0 | H21: =SUM(G21*E21) -> 0
A22: 90878822 | B22: Wohnzimmer 1 | D22: Typ21 700mm | E22: 1.029 | G22: =VALUE('Ablesung Gneiting'!F5) -> 252 | H22: =SUM(G22*E22) -> 259.308
A23: 90878823 | B23: Wohnzimmer 2 | D23: Typ22 700mm | E23: 1.335 | G23: =VALUE('Ablesung Gneiting'!F6) -> 441 | H23: =SUM(G23*E23) -> 588.735
A24: 90878824 | B24: Wohnzimmer 3 | D24: Typ22 700mm | E24: 1.335 | G24: =VALUE('Ablesung Gneiting'!F7) -> 0 | H24: =SUM(G24*E24) -> 0
A25: 90878825 | B25: Bad unten | D25: Typ22 600mm | E25: 1.144 | G25: =VALUE('Ablesung Gneiting'!F8) -> 6 | H25: =SUM(G25*E25) -> 6.864
A26: 90878826 | B26: Handtuchhalter | D26: Sondertyp 1170mm | E26: 0.812 | G26: =VALUE('Ablesung Gneiting'!F9) -> 27 | H26: =SUM(G26*E26) -> 21.924
A27: 90878827 | B27: Arbeitszimmer | D27: Typ22 600mm | E27: 1.144 | G27: =VALUE('Ablesung Gneiting'!F10) -> 148 | H27: =SUM(G27*E27) -> 169.312
A28: 90878828 | B28: Flur oben | D28: Typ22 600mm | E28: 1.144 | G28: =VALUE('Ablesung Gneiting'!F11) -> 145 | H28: =SUM(G28*E28) -> 165.88
A29: 90878829 | B29: Schalfzimmer 1 | D29: Typ33 800mm | E29: 1.344 | G29: =VALUE('Ablesung Gneiting'!F12) -> 85 | H29: =SUM(G29*E29) -> 114.24
A30: 90878830 | B30: Schlafzimmer 2 | D30: Typ33 800mm | E30: 1.344 | G30: =VALUE('Ablesung Gneiting'!F13) -> 148 | H30: =SUM(G30*E30) -> 198.912
A31: 90878831 | B31: Bad oben | D31: Typ22 600mm | E31: 1.144 | G31: =VALUE('Ablesung Gneiting'!F14) -> 8 | H31: =SUM(G31*E31) -> 9.152
A32: Verbrauch | G32: Summe: | H32: =SUM(H28+H29+H30+H31+H20+H21+H22+H23+H24+H25+H26+H27) -> 1534.327
A34: Warmwasserzähler | C34: Datum | D34: Typ | E34: Faktor | F34: Ablesewert alt | G34: Ablesewert neu | H34: Verbrauch
A35: 60431048 | B35: B | D35: Techem | E35: 1 | F35: =VALUE('Ablesung Gneiting'!E17) -> 43.4 | G35: =VALUE('Ablesung Gneiting'!F17) -> 46.994 | H35: =SUM(G35-F35) -> 3.594
A36: 60573468 | B36: WC | D36: Techem | E36: 1 | F36: =VALUE('Ablesung Gneiting'!E18) -> 19 | G36: =VALUE('Ablesung Gneiting'!F18) -> 19.506 | H36: =SUM(G36-F36) -> 0.506
G37: Summe: | H37: =SUM(H36+H35) -> 4.1
A39: Kaltwasserzähler | C39: Datum | D39: Typ | E39: Faktor | F39: Ablesewert alt | G39: Ablesewert neu | H39: Verbrauch
A40: 37425698 | B40: B | D40: Techem | E40: 1 | F40: =VALUE('Ablesung Gneiting'!E20) -> 34.8 | G40: =VALUE('Ablesung Gneiting'!F20) -> 36.831 | H40: =SUM(G40-F40) -> 2.031
A41: 37425652 | B41: WC | D41: Techem | E41: 1 | F41: =VALUE('Ablesung Gneiting'!E21) -> 435.4 | G41: =VALUE('Ablesung Gneiting'!F21) -> 445.152 | H41: =SUM(G41-F41) -> 9.752
A42: 02235773 | B42: WK | D42: Techem | E42: 1 | F42: =VALUE('Ablesung Gneiting'!E22) -> 50.1 | G42: =VALUE('Ablesung Gneiting'!F22) -> 52.27 | H42: =SUM(G42-F42) -> 2.17
G43: Summe: | H43: =SUM(H40+H42+H41) -> 13.953

Sheet W607 Gneiting
A1: Hausverwaltung Thomas Becker, Uhlandstr. 12, 72636 Frickenhausen
A3: Herrn Markus Gneiting Max-Reger Str. 26 72636 Frickenhausen | G3: =TODAY() -> 46119
A4: Abrechnung 2025
A5: Wohnung Nr.6 Uhlandstr.12, Frickenhausen Abrechnung vom | F5: 01.01.2025 | G5: bis 31.12.2025
A6: ___________________________________________________________________________________________________
A7: Bezeichnung | C7: Gesamt in € | D7: Gesamt | E7: Schlüsselbezeichnung | F7: Umlage | G7: Ihr Umlageanteil in €
D8: schlüssel | F8: schlüssel
A9: ___________________________________________________________________________________________________
A10: Vergütung Techn. Hausbetr. | C10: =VALUE('Zahlungen 2025'!I19) -> 2400 | D10: 6 | E10: Wohneinheiten | F10: 1 | G10: =SUM(C10/D10*F10) -> 400
A12: Heizung Verbrauch | C12: =VALUE(Hauptabrechnung!$F$41) -> 5692.54 | D12: 1 | E12: Abrechnung | F12: 1 | G12: =VALUE(Gneiting!$H$13) -> 600.47952
A14: Heizung Wartung/Rep. | C14: =SUM(C15+C16+C18) -> 404.76 | D14: 6 | E14: Wohneinheiten | F14: 1 | G14: =SUM(C14/D14*F14) -> 67.46
A15: Schornsteinfeger | C15: =VALUE('Zahlungen 2025'!D42) -> 99.81
A16: Wartung Baur | C16: =VALUE('Zahlungen 2025'!I42) -> 304.95
A19: Allgemein Strom | C19: =VALUE('Zahlungen 2025'!B42) -> 526.3 | D19: 6 | E19: Wohneinheiten | F19: 1 | G19: =SUM(C19/D19*F19) -> 87.716667
A21: Müllgebühren | C21: =VALUE('Zahlungen 2025'!F42) -> 496.8 | D21: 10 | E21: Personen | F21: 1 | G21: =SUM(C21/D21*F21) -> 49.68
A23: Legionellen Prüfung | C23: 0 | D23: 6 | E23: Wohneinheiten | F23: 1 | G23: =SUM(C23/D23*F23) -> 0
A25: Versicherungen | C25: =SUM(C26+C27) -> 1787.29 | D25: 6 | E25: Miteigent. Anteil | F25: 1 | G25: =SUM(C25/D25*F25) -> 297.88167
A26: Geb. mit Feuer | C26: =VALUE('Zahlungen 2025'!C24) -> 1726.84
A27: Haus-Haftpflicht | C27: =VALUE('Zahlungen 2025'!C23) -> 60.45
A29: Reparaturen/Anschaffungen | C29: 0 | D29: 6 | E29: Wohneinheiten | F29: 1 | G29: =SUM(C29/D29*F29) -> 0
A31: Haus & Grund Mitgliedschaft | C31: =VALUE('Zahlungen 2025'!H42) -> 50 | D31: 6 | E31: Wohneinheiten | F31: 1 | G31: =C31/D31 -> 8.3333333
A33: Nebenkosten Geldverkehr | C33: =VALUE('Zahlungen 2025'!E42) -> 172.95 | D33: 6 | E33: Wohneinheiten | F33: 1 | G33: =C33/D33 -> 28.825
A35: Rücklagen 2024 | C35: =VALUE('Zahlungen 2025'!J19) -> 6000 | D35: 6 | E35: Wohneinheiten | F35: 1 | G35: =SUM(C35/D35*F35) -> 1000
A37: Gesamt | C37: =SUM(C10+C12+C14+C19+C21+C23+C25+C29+C31+C33+C35) -> 17530.64 | G37: =SUM(G10+G12+G14+G19+G21+G22+G23+G25+G29+G31+G33+G35) -> 2540.3762
A38: _________________________________________________________________________________________________________
A40: Vorausszahlungen 2025 | G40: =VALUE('Zahlungen 2025'!G19) -> 2640
A41: _________________________________________________________________________________________________________
A43: Differenzbetrag | E43: Ihre Rückzahlung beträgt: | G43: =SUM(G40-G37) -> 99.623812
A47: Bankverbindung: KSK Esslingen IBAN DE70 6115 0020 0008 1610 37
A48: weg.uhlandstr.12@gmx.de

Sheet Ablesung Gneiting
A1: Gneiting | B1: Ableseprotokoll Verbrauch 2025 | E1: Whg. 6
A2: Heizkostenverteiler | B2: Ort | C2: Heizungstyp | D2: Faktor | E2: Ablesewert alt | F2: Ablesewert
A3: 90878820 | B3: Flur | C3: Typ22 600mm | D3: 1.144 | E3: 0 | F3: 0
A4: 90878821 | B4: Küche | C4: Typ22 500mm | D4: 0.954 | E4: 12 | F4: 0
A5: 90878822 | B5: Wohnzimmer 1 | C5: Typ21 700mm | D5: 1.029 | E5: 235 | F5: 252
A6: 90878823 | B6: Wohnzimmer 2 | C6: Typ22 700mm | D6: 1.335 | E6: 447 | F6: 441
A7: 90878824 | B7: Wohnzimmer 3 | C7: Typ22 700mm | D7: 1.335 | E7: 0 | F7: 0
A8: 90878825 | B8: Bad unten | C8: Typ22 600mm | D8: 1.144 | E8: 0 | F8: 6
A9: 90878826 | B9: Handtuchhalter | C9: Sondertyp 1170mm | D9: 0.812 | E9: 13 | F9: 27
A10: 90878827 | B10: Kinderzimmer | C10: Typ22 600mm | D10: 1.144 | E10: 102 | F10: 148
A11: 90878828 | B11: Flur oben | C11: Typ22 600mm | D11: 1.144 | E11: 121 | F11: 145
A12: 90878829 | B12: Schalfzimmer 1 | C12: Typ33 800mm | D12: 1.344 | E12: 10 | F12: 85
A13: 90878830 | B13: Schlafzimmer 2 | C13: Typ33 800mm | D13: 1.344 | E13: 249 | F13: 148
A14: 90878831 | B14: Bad oben | C14: Typ22 600mm | D14: 1.144 | E14: 22 | F14: 8
A16: Warmwasserzähler | B16: Bad | E16: Ablesewert alt
A17: 60431048 | B17: Bad | C17: neu | E17: 43.4 | F17: 46.994
A18: 60573468 | B18: WC | C18: neu | E18: 19 | F18: 19.506
A19: Kaltwasserzähler | B19: Ort
A20: 84701234 | B20: Bad | C20: neu | E20: 34.8 | F20: 36.831
A21: 84701242 | B21: WC | C21: 44198 | E21: 435.4 | F21: 445.152
A22: 190117683 | B22: Waschmaschine | C22: 44198 | E22: 50.1 | F22: 52.27
D23: Summe:
A24: Datum | B24: Unterschrift Abgelesener | D24: Unterschrift Ablesender

Sheet Weiß-Fudisch
A1: Markus Gneiting, Max Reger Str. 26, 72636 Frickenhausen
